// InfiniPizza!

const waitOne = () =>
  new Promise((resolve) => {
    setTimeout(() => resolve(1), 500)
  })

const waitTwo = () =>
  new Promise((resolve) => {
    setTimeout(() => resolve(2), 1000)
  })

const boomBox = () =>
  new Promise((resolve, reject) => {
    setTimeout(() => {
      console.log(`boomBox called`)
      reject('Database says no')

      // An error here blows the whole stack even if there is a promise.catch()
      throw new Error('Database goes boom') 
    }, 750)
  })

// An array of Promises
const tasks = [waitOne(),boomBox(), waitTwo(), waitOne(), boomBox()]

const successReport = (someData: any) => {
  console.log('Success all finished!', someData)
}

const errorHandler = (someError: any) => {
  console.error('There was an error, please try again later...', someError)
}

console.log('Start now...')
Promise.allSettled(tasks)
  .then(successReport) // [1,2,1, Boom] an array of all the Settled values
  .catch(errorHandler) // Not invoked even if there is an Error
console.log('...Done')

export {}
